Traceback (most recent call last):
  File "/Users/ho/github/reinforcement_learning_coin_trader/main.py", line 33, in <module>
    dt_str = dt_object.strftime("%Y-%m-%d %H:%M")
KeyboardInterrupt
Traceback (most recent call last):
  File "/Users/ho/opt/anaconda3/envs/rlt/lib/python3.9/site-packages/urllib3/connection.py", line 174, in _new_conn
    conn = connection.create_connection(
  File "/Users/ho/opt/anaconda3/envs/rlt/lib/python3.9/site-packages/urllib3/util/connection.py", line 72, in create_connection
    for res in socket.getaddrinfo(host, port, family, socket.SOCK_STREAM):
  File "/Users/ho/opt/anaconda3/envs/rlt/lib/python3.9/socket.py", line 954, in getaddrinfo
    for res in _socket.getaddrinfo(host, port, family, type, proto, flags):
socket.gaierror: [Errno 8] nodename nor servname provided, or not known

During handling of the above exception, another exception occurred:

Traceback (most recent call last):
  File "/Users/ho/opt/anaconda3/envs/rlt/lib/python3.9/site-packages/urllib3/connectionpool.py", line 703, in urlopen
    httplib_response = self._make_request(
  File "/Users/ho/opt/anaconda3/envs/rlt/lib/python3.9/site-packages/urllib3/connectionpool.py", line 386, in _make_request
    self._validate_conn(conn)
  File "/Users/ho/opt/anaconda3/envs/rlt/lib/python3.9/site-packages/urllib3/connectionpool.py", line 1042, in _validate_conn
    conn.connect()
  File "/Users/ho/opt/anaconda3/envs/rlt/lib/python3.9/site-packages/urllib3/connection.py", line 358, in connect
    self.sock = conn = self._new_conn()
  File "/Users/ho/opt/anaconda3/envs/rlt/lib/python3.9/site-packages/urllib3/connection.py", line 186, in _new_conn
    raise NewConnectionError(
urllib3.exceptions.NewConnectionError: <urllib3.connection.HTTPSConnection object at 0x7fde186762e0>: Failed to establish a new connection: [Errno 8] nodename nor servname provided, or not known

During handling of the above exception, another exception occurred:

Traceback (most recent call last):
  File "/Users/ho/opt/anaconda3/envs/rlt/lib/python3.9/site-packages/requests/adapters.py", line 489, in send
    resp = conn.urlopen(
  File "/Users/ho/opt/anaconda3/envs/rlt/lib/python3.9/site-packages/urllib3/connectionpool.py", line 787, in urlopen
    retries = retries.increment(
  File "/Users/ho/opt/anaconda3/envs/rlt/lib/python3.9/site-packages/urllib3/util/retry.py", line 592, in increment
    raise MaxRetryError(_pool, url, error or ResponseError(cause))
urllib3.exceptions.MaxRetryError: HTTPSConnectionPool(host='api.binance.com', port=443): Max retries exceeded with url: /api/v3/klines?symbol=BTCUSDT&interval=5m&limit=1 (Caused by NewConnectionError('<urllib3.connection.HTTPSConnection object at 0x7fde186762e0>: Failed to establish a new connection: [Errno 8] nodename nor servname provided, or not known'))

During handling of the above exception, another exception occurred:

Traceback (most recent call last):
  File "/Users/ho/github/reinforcement_learning_coin_trader/main.py", line 14, in <module>
    df = pd.read_csv("btc_usdt_ohlcv.csv")
  File "/Users/ho/opt/anaconda3/envs/rlt/lib/python3.9/site-packages/requests/api.py", line 73, in get
    return request("get", url, params=params, **kwargs)
  File "/Users/ho/opt/anaconda3/envs/rlt/lib/python3.9/site-packages/requests/api.py", line 59, in request
    return session.request(method=method, url=url, **kwargs)
  File "/Users/ho/opt/anaconda3/envs/rlt/lib/python3.9/site-packages/requests/sessions.py", line 587, in request
    resp = self.send(prep, **send_kwargs)
  File "/Users/ho/opt/anaconda3/envs/rlt/lib/python3.9/site-packages/requests/sessions.py", line 701, in send
    r = adapter.send(request, **kwargs)
  File "/Users/ho/opt/anaconda3/envs/rlt/lib/python3.9/site-packages/requests/adapters.py", line 565, in send
    raise ConnectionError(e, request=request)
requests.exceptions.ConnectionError: HTTPSConnectionPool(host='api.binance.com', port=443): Max retries exceeded with url: /api/v3/klines?symbol=BTCUSDT&interval=5m&limit=1 (Caused by NewConnectionError('<urllib3.connection.HTTPSConnection object at 0x7fde186762e0>: Failed to establish a new connection: [Errno 8] nodename nor servname provided, or not known'))
Traceback (most recent call last):
  File "/Users/ho/opt/anaconda3/envs/rlt/lib/python3.9/site-packages/urllib3/connection.py", line 174, in _new_conn
    conn = connection.create_connection(
  File "/Users/ho/opt/anaconda3/envs/rlt/lib/python3.9/site-packages/urllib3/util/connection.py", line 72, in create_connection
    for res in socket.getaddrinfo(host, port, family, socket.SOCK_STREAM):
  File "/Users/ho/opt/anaconda3/envs/rlt/lib/python3.9/socket.py", line 954, in getaddrinfo
    for res in _socket.getaddrinfo(host, port, family, type, proto, flags):
socket.gaierror: [Errno 8] nodename nor servname provided, or not known

During handling of the above exception, another exception occurred:

Traceback (most recent call last):
  File "/Users/ho/opt/anaconda3/envs/rlt/lib/python3.9/site-packages/urllib3/connectionpool.py", line 703, in urlopen
    httplib_response = self._make_request(
  File "/Users/ho/opt/anaconda3/envs/rlt/lib/python3.9/site-packages/urllib3/connectionpool.py", line 386, in _make_request
    self._validate_conn(conn)
  File "/Users/ho/opt/anaconda3/envs/rlt/lib/python3.9/site-packages/urllib3/connectionpool.py", line 1042, in _validate_conn
    conn.connect()
  File "/Users/ho/opt/anaconda3/envs/rlt/lib/python3.9/site-packages/urllib3/connection.py", line 358, in connect
    self.sock = conn = self._new_conn()
  File "/Users/ho/opt/anaconda3/envs/rlt/lib/python3.9/site-packages/urllib3/connection.py", line 186, in _new_conn
    raise NewConnectionError(
urllib3.exceptions.NewConnectionError: <urllib3.connection.HTTPSConnection object at 0x7fcc008b8100>: Failed to establish a new connection: [Errno 8] nodename nor servname provided, or not known

During handling of the above exception, another exception occurred:

Traceback (most recent call last):
  File "/Users/ho/opt/anaconda3/envs/rlt/lib/python3.9/site-packages/requests/adapters.py", line 489, in send
    resp = conn.urlopen(
  File "/Users/ho/opt/anaconda3/envs/rlt/lib/python3.9/site-packages/urllib3/connectionpool.py", line 787, in urlopen
    retries = retries.increment(
  File "/Users/ho/opt/anaconda3/envs/rlt/lib/python3.9/site-packages/urllib3/util/retry.py", line 592, in increment
    raise MaxRetryError(_pool, url, error or ResponseError(cause))
urllib3.exceptions.MaxRetryError: HTTPSConnectionPool(host='api.binance.com', port=443): Max retries exceeded with url: /api/v3/klines?symbol=BTCUSDT&interval=5m&limit=288 (Caused by NewConnectionError('<urllib3.connection.HTTPSConnection object at 0x7fcc008b8100>: Failed to establish a new connection: [Errno 8] nodename nor servname provided, or not known'))

During handling of the above exception, another exception occurred:

Traceback (most recent call last):
  File "/Users/ho/github/reinforcement_learning_coin_trader/main.py", line 24, in <module>
    response = requests.get(url, params=params)
  File "/Users/ho/opt/anaconda3/envs/rlt/lib/python3.9/site-packages/requests/api.py", line 73, in get
    return request("get", url, params=params, **kwargs)
  File "/Users/ho/opt/anaconda3/envs/rlt/lib/python3.9/site-packages/requests/api.py", line 59, in request
    return session.request(method=method, url=url, **kwargs)
  File "/Users/ho/opt/anaconda3/envs/rlt/lib/python3.9/site-packages/requests/sessions.py", line 587, in request
    resp = self.send(prep, **send_kwargs)
  File "/Users/ho/opt/anaconda3/envs/rlt/lib/python3.9/site-packages/requests/sessions.py", line 701, in send
    r = adapter.send(request, **kwargs)
  File "/Users/ho/opt/anaconda3/envs/rlt/lib/python3.9/site-packages/requests/adapters.py", line 565, in send
    raise ConnectionError(e, request=request)
requests.exceptions.ConnectionError: HTTPSConnectionPool(host='api.binance.com', port=443): Max retries exceeded with url: /api/v3/klines?symbol=BTCUSDT&interval=5m&limit=288 (Caused by NewConnectionError('<urllib3.connection.HTTPSConnection object at 0x7fcc008b8100>: Failed to establish a new connection: [Errno 8] nodename nor servname provided, or not known'))
Traceback (most recent call last):
  File "/Users/ho/opt/anaconda3/envs/rlt/lib/python3.9/site-packages/urllib3/connection.py", line 174, in _new_conn
    conn = connection.create_connection(
  File "/Users/ho/opt/anaconda3/envs/rlt/lib/python3.9/site-packages/urllib3/util/connection.py", line 72, in create_connection
    for res in socket.getaddrinfo(host, port, family, socket.SOCK_STREAM):
  File "/Users/ho/opt/anaconda3/envs/rlt/lib/python3.9/socket.py", line 954, in getaddrinfo
    for res in _socket.getaddrinfo(host, port, family, type, proto, flags):
socket.gaierror: [Errno 8] nodename nor servname provided, or not known

During handling of the above exception, another exception occurred:

Traceback (most recent call last):
  File "/Users/ho/opt/anaconda3/envs/rlt/lib/python3.9/site-packages/urllib3/connectionpool.py", line 703, in urlopen
    httplib_response = self._make_request(
  File "/Users/ho/opt/anaconda3/envs/rlt/lib/python3.9/site-packages/urllib3/connectionpool.py", line 386, in _make_request
    self._validate_conn(conn)
  File "/Users/ho/opt/anaconda3/envs/rlt/lib/python3.9/site-packages/urllib3/connectionpool.py", line 1042, in _validate_conn
    conn.connect()
  File "/Users/ho/opt/anaconda3/envs/rlt/lib/python3.9/site-packages/urllib3/connection.py", line 358, in connect
    self.sock = conn = self._new_conn()
  File "/Users/ho/opt/anaconda3/envs/rlt/lib/python3.9/site-packages/urllib3/connection.py", line 186, in _new_conn
    raise NewConnectionError(
urllib3.exceptions.NewConnectionError: <urllib3.connection.HTTPSConnection object at 0x7fd089229f40>: Failed to establish a new connection: [Errno 8] nodename nor servname provided, or not known

During handling of the above exception, another exception occurred:

Traceback (most recent call last):
  File "/Users/ho/opt/anaconda3/envs/rlt/lib/python3.9/site-packages/requests/adapters.py", line 489, in send
    resp = conn.urlopen(
  File "/Users/ho/opt/anaconda3/envs/rlt/lib/python3.9/site-packages/urllib3/connectionpool.py", line 787, in urlopen
    retries = retries.increment(
  File "/Users/ho/opt/anaconda3/envs/rlt/lib/python3.9/site-packages/urllib3/util/retry.py", line 592, in increment
    raise MaxRetryError(_pool, url, error or ResponseError(cause))
urllib3.exceptions.MaxRetryError: HTTPSConnectionPool(host='api.binance.com', port=443): Max retries exceeded with url: /api/v3/klines?symbol=BTCUSDT&interval=5m&limit=288 (Caused by NewConnectionError('<urllib3.connection.HTTPSConnection object at 0x7fd089229f40>: Failed to establish a new connection: [Errno 8] nodename nor servname provided, or not known'))

During handling of the above exception, another exception occurred:

Traceback (most recent call last):
  File "/Users/ho/github/reinforcement_learning_coin_trader/main.py", line 24, in <module>
    response = requests.get(url, params=params)
  File "/Users/ho/opt/anaconda3/envs/rlt/lib/python3.9/site-packages/requests/api.py", line 73, in get
    return request("get", url, params=params, **kwargs)
  File "/Users/ho/opt/anaconda3/envs/rlt/lib/python3.9/site-packages/requests/api.py", line 59, in request
    return session.request(method=method, url=url, **kwargs)
  File "/Users/ho/opt/anaconda3/envs/rlt/lib/python3.9/site-packages/requests/sessions.py", line 587, in request
    resp = self.send(prep, **send_kwargs)
  File "/Users/ho/opt/anaconda3/envs/rlt/lib/python3.9/site-packages/requests/sessions.py", line 701, in send
    r = adapter.send(request, **kwargs)
  File "/Users/ho/opt/anaconda3/envs/rlt/lib/python3.9/site-packages/requests/adapters.py", line 565, in send
    raise ConnectionError(e, request=request)
requests.exceptions.ConnectionError: HTTPSConnectionPool(host='api.binance.com', port=443): Max retries exceeded with url: /api/v3/klines?symbol=BTCUSDT&interval=5m&limit=288 (Caused by NewConnectionError('<urllib3.connection.HTTPSConnection object at 0x7fd089229f40>: Failed to establish a new connection: [Errno 8] nodename nor servname provided, or not known'))
Traceback (most recent call last):
  File "/Users/ho/opt/anaconda3/envs/rlt/lib/python3.9/site-packages/urllib3/connection.py", line 174, in _new_conn
    conn = connection.create_connection(
  File "/Users/ho/opt/anaconda3/envs/rlt/lib/python3.9/site-packages/urllib3/util/connection.py", line 72, in create_connection
    for res in socket.getaddrinfo(host, port, family, socket.SOCK_STREAM):
  File "/Users/ho/opt/anaconda3/envs/rlt/lib/python3.9/socket.py", line 954, in getaddrinfo
    for res in _socket.getaddrinfo(host, port, family, type, proto, flags):
socket.gaierror: [Errno 8] nodename nor servname provided, or not known

During handling of the above exception, another exception occurred:

Traceback (most recent call last):
  File "/Users/ho/opt/anaconda3/envs/rlt/lib/python3.9/site-packages/urllib3/connectionpool.py", line 703, in urlopen
    httplib_response = self._make_request(
  File "/Users/ho/opt/anaconda3/envs/rlt/lib/python3.9/site-packages/urllib3/connectionpool.py", line 386, in _make_request
    self._validate_conn(conn)
  File "/Users/ho/opt/anaconda3/envs/rlt/lib/python3.9/site-packages/urllib3/connectionpool.py", line 1042, in _validate_conn
    conn.connect()
  File "/Users/ho/opt/anaconda3/envs/rlt/lib/python3.9/site-packages/urllib3/connection.py", line 358, in connect
    self.sock = conn = self._new_conn()
  File "/Users/ho/opt/anaconda3/envs/rlt/lib/python3.9/site-packages/urllib3/connection.py", line 186, in _new_conn
    raise NewConnectionError(
urllib3.exceptions.NewConnectionError: <urllib3.connection.HTTPSConnection object at 0x7f982072f3d0>: Failed to establish a new connection: [Errno 8] nodename nor servname provided, or not known

During handling of the above exception, another exception occurred:

Traceback (most recent call last):
  File "/Users/ho/opt/anaconda3/envs/rlt/lib/python3.9/site-packages/requests/adapters.py", line 489, in send
    resp = conn.urlopen(
  File "/Users/ho/opt/anaconda3/envs/rlt/lib/python3.9/site-packages/urllib3/connectionpool.py", line 787, in urlopen
    retries = retries.increment(
  File "/Users/ho/opt/anaconda3/envs/rlt/lib/python3.9/site-packages/urllib3/util/retry.py", line 592, in increment
    raise MaxRetryError(_pool, url, error or ResponseError(cause))
urllib3.exceptions.MaxRetryError: HTTPSConnectionPool(host='api.binance.com', port=443): Max retries exceeded with url: /api/v3/klines?symbol=BTCUSDT&interval=5m&limit=1 (Caused by NewConnectionError('<urllib3.connection.HTTPSConnection object at 0x7f982072f3d0>: Failed to establish a new connection: [Errno 8] nodename nor servname provided, or not known'))

During handling of the above exception, another exception occurred:

Traceback (most recent call last):
  File "/Users/ho/github/reinforcement_learning_coin_trader/main.py", line 24, in <module>
    response = requests.get(url, params=params)
  File "/Users/ho/opt/anaconda3/envs/rlt/lib/python3.9/site-packages/requests/api.py", line 73, in get
    return request("get", url, params=params, **kwargs)
  File "/Users/ho/opt/anaconda3/envs/rlt/lib/python3.9/site-packages/requests/api.py", line 59, in request
    return session.request(method=method, url=url, **kwargs)
  File "/Users/ho/opt/anaconda3/envs/rlt/lib/python3.9/site-packages/requests/sessions.py", line 587, in request
    resp = self.send(prep, **send_kwargs)
  File "/Users/ho/opt/anaconda3/envs/rlt/lib/python3.9/site-packages/requests/sessions.py", line 701, in send
    r = adapter.send(request, **kwargs)
  File "/Users/ho/opt/anaconda3/envs/rlt/lib/python3.9/site-packages/requests/adapters.py", line 565, in send
    raise ConnectionError(e, request=request)
requests.exceptions.ConnectionError: HTTPSConnectionPool(host='api.binance.com', port=443): Max retries exceeded with url: /api/v3/klines?symbol=BTCUSDT&interval=5m&limit=1 (Caused by NewConnectionError('<urllib3.connection.HTTPSConnection object at 0x7f982072f3d0>: Failed to establish a new connection: [Errno 8] nodename nor servname provided, or not known'))
Traceback (most recent call last):
  File "/Users/ho/github/reinforcement_learning_coin_trader/main.py", line 43, in <module>
    time.sleep(300)  # 5분 대기
  File "/Users/ho/opt/anaconda3/envs/rlt/lib/python3.9/site-packages/pandas/util/_decorators.py", line 331, in wrapper
    return func(*args, **kwargs)
  File "/Users/ho/opt/anaconda3/envs/rlt/lib/python3.9/site-packages/pandas/core/frame.py", line 6672, in drop_duplicates
    duplicated = self.duplicated(subset, keep=keep)
  File "/Users/ho/opt/anaconda3/envs/rlt/lib/python3.9/site-packages/pandas/core/frame.py", line 6806, in duplicated
    raise KeyError(Index(diff))
KeyError: Index(['Timestamp'], dtype='object')
